---
title: 错误处理机制
date: 2018-07-15 23:31:58
tags: [错误处理, js原生]
categories: js原生
---

## Error 实例对象
JavaScript 解析或运行时，一旦发生错误，引擎就会抛出一个错误对象。
```JavaScript
var err = new Error('出错了');
err.message // "出错了"
```
<!--more-->
### error 实例的属性和方法
* message：错误提示信息
* 错误名称（非标准属性
* stack：错误的堆栈（非标准属性）

```JavaScript
  function throwit() {
    throw new Error('');
  }

  function catchit() {
    try {
      throwit();
    } catch(e) {
      console.log(e.stack); // print stack trace
    }
  }
  // 错误堆栈的最内层是throwit函数，然后是catchit函数，最后是函数的运行环境。
  catchit()
  // Error
  //    at throwit (~/examples/throwcatch.js:9:11)
  //    at catchit (~/examples/throwcatch.js:3:9)
  //    at repl:1:5 
```
## 原生错误类型
> Error实例对象是最一般的错误类型，在它的基础上，JavaScript 还定义了其他6种错误对象。也就是说，存在Error的6个派生对象。
### SyntaxError 对象
`SyntaxError`对象是解析代码时发生的语法错误。
```JavaScript
  // 变量名错误
  var 1a;
  // Uncaught SyntaxError: Invalid or unexpected token

  // 缺少括号
  console.log 'hello');
  // Uncaught SyntaxError: Unexpected string

```
### ReferenceError 对象
`referenceError`对象是引用一个不存在的变量时发生的错误。
```JavaScript
  // 使用一个不存在的变量
  unknownVariable
  // Uncaught ReferenceError: unknownVariable is not defined
```
### RangeError 对象
`RangeError`对象是一个值超出有效范围时发生的错误。主要有几种情况，一是数组长度为负数，二是Number对象的方法参数超出范围，以及函数堆栈超过最大值。
```JavaScript
  // 数组长度不得为负数
  new Array(-1)
  // Uncaught RangeError: Invalid array length
```
### TypeError 对象
`TypeError`对象是变量或参数不是预期类型时发生的错误。
```JavaScript
  var obj = {};
  obj.unknownMethod()
  // Uncaught TypeError: obj.unknownMethod is not a function
```
### URIError 对象
`URIError`对象是 URI 相关函数的参数不正确时抛出的错误，主要涉及`encodeURI()`、`decodeURI()`、`encodeURIComponent()`、`decodeURIComponent()`、`escape()`和`unescape()`这六个函数。
```JavaScript
  decodeURI('%2')
  // URIError: URI malformed
```
### EvalError 对象
eval函数没有被正确执行时，会抛出EvalError错误。该错误类型已经不再使用了，只是为了保证与以前代码兼容，才继续保留。
## 自定义错误类型
除了 JavaScript 原生提供的七种错误对象，还可以定义自己的错误对象。
```JavaScript
  function UserError(message) {
    this.message = message || '默认信息';
    this.name = 'UserError';
  }

  UserError.prototype = new Error();
  UserError.prototype.constructor = UserError;
```
## throw语句
throw语句的作用是手动中断程序执行，抛出一个错误。
```JavaScript
  if (x < 0) {
    throw new Error('x 必须为正数');
  }
  // Uncaught ReferenceError: x is not defined
```
throw 可抛出任意类型的值
```JavaScript
// 抛出一个字符串
throw 'Error！'; // Uncaught Error！

// 抛出一个数值
throw 42; // Uncaught 42

// 抛出一个布尔值
throw true; // Uncaught true

// 抛出一个对象
throw {
  toString: function () {
    return 'Error!';
  }
}; // // Uncaught {toString: ƒ}

// 抛出一个自定义错误
function UserError(message) {
  this.message = message || '默认信息';
  this.name = 'UserError';
}

throw new UserError('出错了！'); // Uncaught UserError {message: "出错了！", name: "UserError"}
```
## try...catch 结构
一旦发生错误，程序就中止执行了。JavaScript 提供了`try...catch`结构，允许对错误进行处理，选择是否往下执行。
```JavaScript
  try {
    throw new Error('出错了!');
  } catch (e) {
    console.log(e.name + ": " + e.message);
    console.log(e.stack);
  }
  // Error: 出错了!
  //   at <anonymous>:3:9
  //   ...
```
`catch`代码块捕获错误之后，程序不会中断，会按照正常流程继续执行下去。
```JavaScript
try {
  throw "出错了";
} catch (e) {
  console.log(111);
} 
// 被catch代码块捕获后，程序会继续向下执行
console.log(222); 
// 111
// 222
```
catch代码块之中，还可以再抛出错误，甚至使用嵌套的try...catch结构
```JavaScript
  var n = 100;

  try {
    throw n;
  } catch (e) {
    if (e <= 50) {
      // ...
    } else {
      throw e;
    }
  }
```
## finally
try...catch结构允许在最后添加一个finally代码块，表示不管是否出现错误，都必需在最后运行的语句。
```JavaScript
  function f() {
    try {
      console.log(0);
      throw 'bug';
    } catch(e) {
      console.log(1);
      return true; // 这句原本会延迟到 finally 代码块结束再执行
      console.log(2); // 不会运行
    } finally {
      console.log(3);
      return false; // 这句会覆盖掉前面那句 return
      console.log(4); // 不会运行
    }

    console.log(5); // 不会运行
  }

  var result = f();
  // 0
  // 1
  // 3

  result
  // false


function f() {
  try {
    throw '出错了！';
  } catch(e) {
    console.log('捕捉到内部错误');
    throw e; // 这句原本会等到finally结束再执行
  } finally {
    return false; // 直接返回
  }
}

try {
  f();
} catch(e) {
  // 此处不会执行
  console.log('caught outer "bogus"');
}

//  捕捉到内部错误


```